reported_result/report-92/ART_TFC/output/output3.txt

Limit	1	1	6	8	3	SELL	0	---	0
NewOrderRs	Accepted
	Trades	0
	Orders	1
	Order	Limit	1	1	6	8	3	SELL	0	---	0
	Credits	7
	Credit	1	19
	Credit	2	10
	Credit	3	3
	Credit	4	12
	Credit	5	13
	Credit	6	12
	Credit	7	18
	Ownerships	7
	Ownership	1	58
	Ownership	2	48
	Ownership	3	58
	Ownership	4	76
	Ownership	5	65
	Ownership	6	27
	Ownership	7	24
	ReferencePrice	5
	StaticPriceBandLowerLimit	0.6
	StaticPriceBandUpperLimit	0.8
	TotalShares	100
	OwnershipUpperLimit	0.2
	TickSize	1
	LotSize	1
Iceberg	2	6	7	7	4	BUY 	1	---	0
NewOrderRs	Rejected
	Trades	0
	Orders	1
	Order	Limit	1	1	6	8	3	SELL	0	---	0
	Credits	7
	Credit	1	19
	Credit	2	10
	Credit	3	3
	Credit	4	12
	Credit	5	13
	Credit	6	12
	Credit	7	18
	Ownerships	7
	Ownership	1	58
	Ownership	2	48
	Ownership	3	58
	Ownership	4	76
	Ownership	5	65
	Ownership	6	27
	Ownership	7	24
	ReferencePrice	5
	StaticPriceBandLowerLimit	0.6
	StaticPriceBandUpperLimit	0.8
	TotalShares	100
	OwnershipUpperLimit	0.2
	TickSize	1
	LotSize	1
Iceberg	3	4	5	8	7	BUY 	0	---	0
NewOrderRs	Rejected
	Trades	0
	Orders	1
	Order	Limit	1	1	6	8	3	SELL	0	---	0
	Credits	7
	Credit	1	19
	Credit	2	10
	Credit	3	3
	Credit	4	12
	Credit	5	13
	Credit	6	12
	Credit	7	18
	Ownerships	7
	Ownership	1	58
	Ownership	2	48
	Ownership	3	58
	Ownership	4	76
	Ownership	5	65
	Ownership	6	27
	Ownership	7	24
	ReferencePrice	5
	StaticPriceBandLowerLimit	0.6
	StaticPriceBandUpperLimit	0.8
	TotalShares	100
	OwnershipUpperLimit	0.2
	TickSize	1
	LotSize	1
Limit	4	5	6	2	6	SELL	0	---	0
NewOrderRs	Accepted
	Trades	0
	Orders	2
	Order	Limit	4	5	6	2	6	SELL	0	---	0
	Order	Limit	1	1	6	8	3	SELL	0	---	0
	Credits	7
	Credit	1	19
	Credit	2	10
	Credit	3	3
	Credit	4	12
	Credit	5	13
	Credit	6	12
	Credit	7	18
	Ownerships	7
	Ownership	1	58
	Ownership	2	48
	Ownership	3	58
	Ownership	4	76
	Ownership	5	65
	Ownership	6	27
	Ownership	7	24
	ReferencePrice	5
	StaticPriceBandLowerLimit	0.6
	StaticPriceBandUpperLimit	0.8
	TotalShares	100
	OwnershipUpperLimit	0.2
	TickSize	1
	LotSize	1
CancelOrderRs	Accepted
	Orders	2
	Order	Limit	4	5	6	2	6	SELL	0	---	0
	Order	Limit	1	1	6	8	3	SELL	0	---	0
	Credits	7
	Credit	1	19
	Credit	2	10
	Credit	3	3
	Credit	4	12
	Credit	5	13
	Credit	6	12
	Credit	7	18
	Ownerships	7
	Ownership	1	58
	Ownership	2	48
	Ownership	3	58
	Ownership	4	76
	Ownership	5	65
	Ownership	6	27
	Ownership	7	24
	ReferencePrice	5
	StaticPriceBandLowerLimit	0.6
	StaticPriceBandUpperLimit	0.8
	TotalShares	100
	OwnershipUpperLimit	0.2
	TickSize	1
	LotSize	1
Limit	6	2	7	7	5	BUY 	0	---	0
NewOrderRs	Rejected
	Trades	0
	Orders	2
	Order	Limit	4	5	6	2	6	SELL	0	---	0
	Order	Limit	1	1	6	8	3	SELL	0	---	0
	Credits	7
	Credit	1	19
	Credit	2	10
	Credit	3	3
	Credit	4	12
	Credit	5	13
	Credit	6	12
	Credit	7	18
	Ownerships	7
	Ownership	1	58
	Ownership	2	48
	Ownership	3	58
	Ownership	4	76
	Ownership	5	65
	Ownership	6	27
	Ownership	7	24
	ReferencePrice	5
	StaticPriceBandLowerLimit	0.6
	StaticPriceBandUpperLimit	0.8
	TotalShares	100
	OwnershipUpperLimit	0.2
	TickSize	1
	LotSize	1
Limit	7	5	2	7	6	SELL	0	---	0
NewOrderRs	Accepted
	Trades	0
	Orders	3
	Order	Limit	4	5	6	2	6	SELL	0	---	0
	Order	Limit	7	5	2	7	6	SELL	0	---	0
	Order	Limit	1	1	6	8	3	SELL	0	---	0
	Credits	7
	Credit	1	19
	Credit	2	10
	Credit	3	3
	Credit	4	12
	Credit	5	13
	Credit	6	12
	Credit	7	18
	Ownerships	7
	Ownership	1	58
	Ownership	2	48
	Ownership	3	58
	Ownership	4	76
	Ownership	5	65
	Ownership	6	27
	Ownership	7	24
	ReferencePrice	5
	StaticPriceBandLowerLimit	0.6
	StaticPriceBandUpperLimit	0.8
	TotalShares	100
	OwnershipUpperLimit	0.2
	TickSize	1
	LotSize	1
Iceberg	8	5	1	3	2	SELL	2	---	0
NewOrderRs	Eliminated
	Trades	0
	Orders	3
	Order	Limit	4	5	6	2	6	SELL	0	---	0
	Order	Limit	7	5	2	7	6	SELL	0	---	0
	Order	Limit	1	1	6	8	3	SELL	0	---	0
	Credits	7
	Credit	1	19
	Credit	2	10
	Credit	3	3
	Credit	4	12
	Credit	5	13
	Credit	6	12
	Credit	7	18
	Ownerships	7
	Ownership	1	58
	Ownership	2	48
	Ownership	3	58
	Ownership	4	76
	Ownership	5	65
	Ownership	6	27
	Ownership	7	24
	ReferencePrice	5
	StaticPriceBandLowerLimit	0.6
	StaticPriceBandUpperLimit	0.8
	TotalShares	100
	OwnershipUpperLimit	0.2
	TickSize	1
	LotSize	1
Limit	9	5	1	6	8	BUY 	0	---	0
NewOrderRs	Rejected
	Trades	0
	Orders	3
	Order	Limit	4	5	6	2	6	SELL	0	---	0
	Order	Limit	7	5	2	7	6	SELL	0	---	0
	Order	Limit	1	1	6	8	3	SELL	0	---	0
	Credits	7
	Credit	1	19
	Credit	2	10
	Credit	3	3
	Credit	4	12
	Credit	5	13
	Credit	6	12
	Credit	7	18
	Ownerships	7
	Ownership	1	58
	Ownership	2	48
	Ownership	3	58
	Ownership	4	76
	Ownership	5	65
	Ownership	6	27
	Ownership	7	24
	ReferencePrice	5
	StaticPriceBandLowerLimit	0.6
	StaticPriceBandUpperLimit	0.8
	TotalShares	100
	OwnershipUpperLimit	0.2
	TickSize	1
	LotSize	1
Iceberg	10	5	1	6	1	BUY 	0	---	0
ReplaceOrderRs	Rejected
	Trades	0
	Orders	3
	Order	Limit	4	5	6	2	6	SELL	0	---	0
	Order	Limit	7	5	2	7	6	SELL	0	---	0
	Order	Limit	1	1	6	8	3	SELL	0	---	0
	Credits	7
	Credit	1	19
	Credit	2	10
	Credit	3	3
	Credit	4	12
	Credit	5	13
	Credit	6	12
	Credit	7	18
	Ownerships	7
	Ownership	1	58
	Ownership	2	48
	Ownership	3	58
	Ownership	4	76
	Ownership	5	65
	Ownership	6	27
	Ownership	7	24
	ReferencePrice	5
	StaticPriceBandLowerLimit	0.6
	StaticPriceBandUpperLimit	0.8
	TotalShares	100
	OwnershipUpperLimit	0.2
	TickSize	1
	LotSize	1
