reported_result/report-94/ART_ISP_hs/output/output0.txt

Limit	1	4	5	9	4	SELL	4	---	0
NewOrderRs	Eliminated
	Trades	0
	Orders	0
	Credits	7
	Credit	1	14
	Credit	2	14
	Credit	3	3
	Credit	4	11
	Credit	5	13
	Credit	6	11
	Credit	7	18
	Ownerships	7
	Ownership	1	62
	Ownership	2	35
	Ownership	3	18
	Ownership	4	82
	Ownership	5	79
	Ownership	6	65
	Ownership	7	89
	ReferencePrice	5
	StaticPriceBandLowerLimit	0.6
	StaticPriceBandUpperLimit	0.8
	TotalShares	100
	OwnershipUpperLimit	0.2
	TickSize	1
	LotSize	1
Limit	2	7	2	9	3	SELL	0	---	0
NewOrderRs	Accepted
	Trades	0
	Orders	1
	Order	Limit	2	7	2	9	3	SELL	0	---	0
	Credits	7
	Credit	1	14
	Credit	2	14
	Credit	3	3
	Credit	4	11
	Credit	5	13
	Credit	6	11
	Credit	7	18
	Ownerships	7
	Ownership	1	62
	Ownership	2	35
	Ownership	3	18
	Ownership	4	82
	Ownership	5	79
	Ownership	6	65
	Ownership	7	89
	ReferencePrice	5
	StaticPriceBandLowerLimit	0.6
	StaticPriceBandUpperLimit	0.8
	TotalShares	100
	OwnershipUpperLimit	0.2
	TickSize	1
	LotSize	1
Limit	3	6	5	4	3	BUY 	3	---	0
NewOrderRs	Rejected
	Trades	0
	Orders	1
	Order	Limit	2	7	2	9	3	SELL	0	---	0
	Credits	7
	Credit	1	14
	Credit	2	14
	Credit	3	3
	Credit	4	11
	Credit	5	13
	Credit	6	11
	Credit	7	18
	Ownerships	7
	Ownership	1	62
	Ownership	2	35
	Ownership	3	18
	Ownership	4	82
	Ownership	5	79
	Ownership	6	65
	Ownership	7	89
	ReferencePrice	5
	StaticPriceBandLowerLimit	0.6
	StaticPriceBandUpperLimit	0.8
	TotalShares	100
	OwnershipUpperLimit	0.2
	TickSize	1
	LotSize	1
Iceberg	4	6	2	5	1	SELL	1	---	0
NewOrderRs	Eliminated
	Trades	0
	Orders	1
	Order	Limit	2	7	2	9	3	SELL	0	---	0
	Credits	7
	Credit	1	14
	Credit	2	14
	Credit	3	3
	Credit	4	11
	Credit	5	13
	Credit	6	11
	Credit	7	18
	Ownerships	7
	Ownership	1	62
	Ownership	2	35
	Ownership	3	18
	Ownership	4	82
	Ownership	5	79
	Ownership	6	65
	Ownership	7	89
	ReferencePrice	5
	StaticPriceBandLowerLimit	0.6
	StaticPriceBandUpperLimit	0.8
	TotalShares	100
	OwnershipUpperLimit	0.2
	TickSize	1
	LotSize	1
CancelOrderRs	Rejected
	Orders	1
	Order	Limit	2	7	2	9	3	SELL	0	---	0
	Credits	7
	Credit	1	14
	Credit	2	14
	Credit	3	3
	Credit	4	11
	Credit	5	13
	Credit	6	11
	Credit	7	18
	Ownerships	7
	Ownership	1	62
	Ownership	2	35
	Ownership	3	18
	Ownership	4	82
	Ownership	5	79
	Ownership	6	65
	Ownership	7	89
	ReferencePrice	5
	StaticPriceBandLowerLimit	0.6
	StaticPriceBandUpperLimit	0.8
	TotalShares	100
	OwnershipUpperLimit	0.2
	TickSize	1
	LotSize	1
Iceberg	6	2	4	4	8	SELL	0	---	0
NewOrderRs	Accepted
	Trades	0
	Orders	2
	Order	Iceberg	6	2	4	4	8	SELL	0	---	8
	Order	Limit	2	7	2	9	3	SELL	0	---	0
	Credits	7
	Credit	1	14
	Credit	2	14
	Credit	3	3
	Credit	4	11
	Credit	5	13
	Credit	6	11
	Credit	7	18
	Ownerships	7
	Ownership	1	62
	Ownership	2	35
	Ownership	3	18
	Ownership	4	82
	Ownership	5	79
	Ownership	6	65
	Ownership	7	89
	ReferencePrice	5
	StaticPriceBandLowerLimit	0.6
	StaticPriceBandUpperLimit	0.8
	TotalShares	100
	OwnershipUpperLimit	0.2
	TickSize	1
	LotSize	1
Limit	7	4	2	8	5	SELL	0	---	0
NewOrderRs	Accepted
	Trades	0
	Orders	3
	Order	Iceberg	6	2	4	4	8	SELL	0	---	8
	Order	Limit	7	4	2	8	5	SELL	0	---	0
	Order	Limit	2	7	2	9	3	SELL	0	---	0
	Credits	7
	Credit	1	14
	Credit	2	14
	Credit	3	3
	Credit	4	11
	Credit	5	13
	Credit	6	11
	Credit	7	18
	Ownerships	7
	Ownership	1	62
	Ownership	2	35
	Ownership	3	18
	Ownership	4	82
	Ownership	5	79
	Ownership	6	65
	Ownership	7	89
	ReferencePrice	5
	StaticPriceBandLowerLimit	0.6
	StaticPriceBandUpperLimit	0.8
	TotalShares	100
	OwnershipUpperLimit	0.2
	TickSize	1
	LotSize	1
Iceberg	8	4	1	5	6	BUY 	0	---	0
NewOrderRs	Rejected
	Trades	0
	Orders	3
	Order	Iceberg	6	2	4	4	8	SELL	0	---	8
	Order	Limit	7	4	2	8	5	SELL	0	---	0
	Order	Limit	2	7	2	9	3	SELL	0	---	0
	Credits	7
	Credit	1	14
	Credit	2	14
	Credit	3	3
	Credit	4	11
	Credit	5	13
	Credit	6	11
	Credit	7	18
	Ownerships	7
	Ownership	1	62
	Ownership	2	35
	Ownership	3	18
	Ownership	4	82
	Ownership	5	79
	Ownership	6	65
	Ownership	7	89
	ReferencePrice	5
	StaticPriceBandLowerLimit	0.6
	StaticPriceBandUpperLimit	0.8
	TotalShares	100
	OwnershipUpperLimit	0.2
	TickSize	1
	LotSize	1
Limit	9	1	1	8	5	BUY 	0	FAK	0
NewOrderRs	Rejected
	Trades	0
	Orders	3
	Order	Iceberg	6	2	4	4	8	SELL	0	---	8
	Order	Limit	7	4	2	8	5	SELL	0	---	0
	Order	Limit	2	7	2	9	3	SELL	0	---	0
	Credits	7
	Credit	1	14
	Credit	2	14
	Credit	3	3
	Credit	4	11
	Credit	5	13
	Credit	6	11
	Credit	7	18
	Ownerships	7
	Ownership	1	62
	Ownership	2	35
	Ownership	3	18
	Ownership	4	82
	Ownership	5	79
	Ownership	6	65
	Ownership	7	89
	ReferencePrice	5
	StaticPriceBandLowerLimit	0.6
	StaticPriceBandUpperLimit	0.8
	TotalShares	100
	OwnershipUpperLimit	0.2
	TickSize	1
	LotSize	1
Iceberg	10	1	1	8	3	BUY 	0	---	0
ReplaceOrderRs	Rejected
	Trades	0
	Orders	3
	Order	Iceberg	6	2	4	4	8	SELL	0	---	8
	Order	Limit	7	4	2	8	5	SELL	0	---	0
	Order	Limit	2	7	2	9	3	SELL	0	---	0
	Credits	7
	Credit	1	14
	Credit	2	14
	Credit	3	3
	Credit	4	11
	Credit	5	13
	Credit	6	11
	Credit	7	18
	Ownerships	7
	Ownership	1	62
	Ownership	2	35
	Ownership	3	18
	Ownership	4	82
	Ownership	5	79
	Ownership	6	65
	Ownership	7	89
	ReferencePrice	5
	StaticPriceBandLowerLimit	0.6
	StaticPriceBandUpperLimit	0.8
	TotalShares	100
	OwnershipUpperLimit	0.2
	TickSize	1
	LotSize	1
