reported_result/report-94/ART_TFC/output/output0.txt

Limit	1	6	7	6	2	SELL	0	---	0
NewOrderRs	Accepted
	Trades	0
	Orders	1
	Order	Limit	1	6	7	6	2	SELL	0	---	0
	Credits	7
	Credit	1	17
	Credit	2	11
	Credit	3	11
	Credit	4	15
	Credit	5	17
	Credit	6	10
	Credit	7	10
	Ownerships	7
	Ownership	1	62
	Ownership	2	16
	Ownership	3	82
	Ownership	4	37
	Ownership	5	40
	Ownership	6	64
	Ownership	7	64
	ReferencePrice	5
	StaticPriceBandLowerLimit	0.6
	StaticPriceBandUpperLimit	0.8
	TotalShares	100
	OwnershipUpperLimit	0.2
	TickSize	1
	LotSize	1
Limit	2	1	2	6	6	SELL	0	---	0
NewOrderRs	Accepted
	Trades	0
	Orders	2
	Order	Limit	1	6	7	6	2	SELL	0	---	0
	Order	Limit	2	1	2	6	6	SELL	0	---	0
	Credits	7
	Credit	1	17
	Credit	2	11
	Credit	3	11
	Credit	4	15
	Credit	5	17
	Credit	6	10
	Credit	7	10
	Ownerships	7
	Ownership	1	62
	Ownership	2	16
	Ownership	3	82
	Ownership	4	37
	Ownership	5	40
	Ownership	6	64
	Ownership	7	64
	ReferencePrice	5
	StaticPriceBandLowerLimit	0.6
	StaticPriceBandUpperLimit	0.8
	TotalShares	100
	OwnershipUpperLimit	0.2
	TickSize	1
	LotSize	1
Limit	3	5	6	2	6	SELL	0	---	0
NewOrderRs	Accepted
	Trades	0
	Orders	3
	Order	Limit	3	5	6	2	6	SELL	0	---	0
	Order	Limit	1	6	7	6	2	SELL	0	---	0
	Order	Limit	2	1	2	6	6	SELL	0	---	0
	Credits	7
	Credit	1	17
	Credit	2	11
	Credit	3	11
	Credit	4	15
	Credit	5	17
	Credit	6	10
	Credit	7	10
	Ownerships	7
	Ownership	1	62
	Ownership	2	16
	Ownership	3	82
	Ownership	4	37
	Ownership	5	40
	Ownership	6	64
	Ownership	7	64
	ReferencePrice	5
	StaticPriceBandLowerLimit	0.6
	StaticPriceBandUpperLimit	0.8
	TotalShares	100
	OwnershipUpperLimit	0.2
	TickSize	1
	LotSize	1
Limit	4	6	7	6	7	BUY 	0	FAK	0
NewOrderRs	Rejected
	Trades	0
	Orders	3
	Order	Limit	3	5	6	2	6	SELL	0	---	0
	Order	Limit	1	6	7	6	2	SELL	0	---	0
	Order	Limit	2	1	2	6	6	SELL	0	---	0
	Credits	7
	Credit	1	17
	Credit	2	11
	Credit	3	11
	Credit	4	15
	Credit	5	17
	Credit	6	10
	Credit	7	10
	Ownerships	7
	Ownership	1	62
	Ownership	2	16
	Ownership	3	82
	Ownership	4	37
	Ownership	5	40
	Ownership	6	64
	Ownership	7	64
	ReferencePrice	5
	StaticPriceBandLowerLimit	0.6
	StaticPriceBandUpperLimit	0.8
	TotalShares	100
	OwnershipUpperLimit	0.2
	TickSize	1
	LotSize	1
CancelOrderRs	Rejected
	Orders	3
	Order	Limit	3	5	6	2	6	SELL	0	---	0
	Order	Limit	1	6	7	6	2	SELL	0	---	0
	Order	Limit	2	1	2	6	6	SELL	0	---	0
	Credits	7
	Credit	1	17
	Credit	2	11
	Credit	3	11
	Credit	4	15
	Credit	5	17
	Credit	6	10
	Credit	7	10
	Ownerships	7
	Ownership	1	62
	Ownership	2	16
	Ownership	3	82
	Ownership	4	37
	Ownership	5	40
	Ownership	6	64
	Ownership	7	64
	ReferencePrice	5
	StaticPriceBandLowerLimit	0.6
	StaticPriceBandUpperLimit	0.8
	TotalShares	100
	OwnershipUpperLimit	0.2
	TickSize	1
	LotSize	1
Limit	6	6	7	6	1	BUY 	0	---	0
NewOrderRs	Rejected
	Trades	0
	Orders	3
	Order	Limit	3	5	6	2	6	SELL	0	---	0
	Order	Limit	1	6	7	6	2	SELL	0	---	0
	Order	Limit	2	1	2	6	6	SELL	0	---	0
	Credits	7
	Credit	1	17
	Credit	2	11
	Credit	3	11
	Credit	4	15
	Credit	5	17
	Credit	6	10
	Credit	7	10
	Ownerships	7
	Ownership	1	62
	Ownership	2	16
	Ownership	3	82
	Ownership	4	37
	Ownership	5	40
	Ownership	6	64
	Ownership	7	64
	ReferencePrice	5
	StaticPriceBandLowerLimit	0.6
	StaticPriceBandUpperLimit	0.8
	TotalShares	100
	OwnershipUpperLimit	0.2
	TickSize	1
	LotSize	1
Iceberg	7	6	5	8	6	BUY 	0	---	0
NewOrderRs	Rejected
	Trades	0
	Orders	3
	Order	Limit	3	5	6	2	6	SELL	0	---	0
	Order	Limit	1	6	7	6	2	SELL	0	---	0
	Order	Limit	2	1	2	6	6	SELL	0	---	0
	Credits	7
	Credit	1	17
	Credit	2	11
	Credit	3	11
	Credit	4	15
	Credit	5	17
	Credit	6	10
	Credit	7	10
	Ownerships	7
	Ownership	1	62
	Ownership	2	16
	Ownership	3	82
	Ownership	4	37
	Ownership	5	40
	Ownership	6	64
	Ownership	7	64
	ReferencePrice	5
	StaticPriceBandLowerLimit	0.6
	StaticPriceBandUpperLimit	0.8
	TotalShares	100
	OwnershipUpperLimit	0.2
	TickSize	1
	LotSize	1
Limit	8	1	5	4	3	BUY 	0	FAK	0
NewOrderRs	Rejected
	Trades	0
	Orders	3
	Order	Limit	3	5	6	2	6	SELL	0	---	0
	Order	Limit	1	6	7	6	2	SELL	0	---	0
	Order	Limit	2	1	2	6	6	SELL	0	---	0
	Credits	7
	Credit	1	17
	Credit	2	11
	Credit	3	11
	Credit	4	15
	Credit	5	17
	Credit	6	10
	Credit	7	10
	Ownerships	7
	Ownership	1	62
	Ownership	2	16
	Ownership	3	82
	Ownership	4	37
	Ownership	5	40
	Ownership	6	64
	Ownership	7	64
	ReferencePrice	5
	StaticPriceBandLowerLimit	0.6
	StaticPriceBandUpperLimit	0.8
	TotalShares	100
	OwnershipUpperLimit	0.2
	TickSize	1
	LotSize	1
Iceberg	9	3	6	5	7	BUY 	0	---	0
NewOrderRs	Rejected
	Trades	0
	Orders	3
	Order	Limit	3	5	6	2	6	SELL	0	---	0
	Order	Limit	1	6	7	6	2	SELL	0	---	0
	Order	Limit	2	1	2	6	6	SELL	0	---	0
	Credits	7
	Credit	1	17
	Credit	2	11
	Credit	3	11
	Credit	4	15
	Credit	5	17
	Credit	6	10
	Credit	7	10
	Ownerships	7
	Ownership	1	62
	Ownership	2	16
	Ownership	3	82
	Ownership	4	37
	Ownership	5	40
	Ownership	6	64
	Ownership	7	64
	ReferencePrice	5
	StaticPriceBandLowerLimit	0.6
	StaticPriceBandUpperLimit	0.8
	TotalShares	100
	OwnershipUpperLimit	0.2
	TickSize	1
	LotSize	1
Iceberg	10	3	6	4	2	BUY 	1	---	0
ReplaceOrderRs	Rejected
	Trades	0
	Orders	3
	Order	Limit	3	5	6	2	6	SELL	0	---	0
	Order	Limit	1	6	7	6	2	SELL	0	---	0
	Order	Limit	2	1	2	6	6	SELL	0	---	0
	Credits	7
	Credit	1	17
	Credit	2	11
	Credit	3	11
	Credit	4	15
	Credit	5	17
	Credit	6	10
	Credit	7	10
	Ownerships	7
	Ownership	1	62
	Ownership	2	16
	Ownership	3	82
	Ownership	4	37
	Ownership	5	40
	Ownership	6	64
	Ownership	7	64
	ReferencePrice	5
	StaticPriceBandLowerLimit	0.6
	StaticPriceBandUpperLimit	0.8
	TotalShares	100
	OwnershipUpperLimit	0.2
	TickSize	1
	LotSize	1
